<?xml version="1.0" ?>
<robot name="center_table" xmlns:xacro="http://www.ros.org/wiki/xacro">

<xacro:include filename="$(find center_table_description)/urdf/materials.xacro" />
<xacro:include filename="$(find center_table_description)/urdf/center_table.trans" />
<xacro:include filename="$(find center_table_description)/urdf/center_table.gazebo" />
<link name="base_link">
  <inertial>
    <origin rpy="0 0 0" xyz="6.2690688646506115e-06 -6.26906886476561e-06 0.008885614402956097"/>
    <mass value="0.8536576395512193"/>
    <inertia ixx="0.000853" ixy="-0.0" ixz="-0.0" iyy="0.000853" iyz="0.0" izz="0.00131"/>
  </inertial>
  <visual>
    <origin rpy="0 0 0" xyz="0 0 0"/>
    <geometry>
      <mesh filename="package://center_table_description/meshes/base_link.stl" scale="0.001 0.001 0.001"/>
    </geometry>
    <material name="silver"/>
  </visual>
  <collision>
    <origin rpy="0 0 0" xyz="0 0 0"/>
    <geometry>
      <mesh filename="package://center_table_description/meshes/base_link.stl" scale="0.001 0.001 0.001"/>
    </geometry>
  </collision>
</link>

<link name="Component4_1">
  <inertial>
    <origin rpy="0 0 0" xyz="5.423687868282483e-18 -0.06444432490829055 0.02126691756149582"/>
    <mass value="0.004666664302202742"/>
    <inertia ixx="1e-06" ixy="0.0" ixz="0.0" iyy="0.0" iyz="0.0" izz="0.0"/>
  </inertial>
  <visual>
    <origin rpy="0 0 0" xyz="-0.0 0.022766 -0.079343"/>
    <geometry>
      <mesh filename="package://center_table_description/meshes/Component4_1.stl" scale="0.001 0.001 0.001"/>
    </geometry>
    <material name="silver"/>
  </visual>
  <collision>
    <origin rpy="0 0 0" xyz="-0.0 0.022766 -0.079343"/>
    <geometry>
      <mesh filename="package://center_table_description/meshes/Component4_1.stl" scale="0.001 0.001 0.001"/>
    </geometry>
  </collision>
</link>

<link name="Component3_1">
  <inertial>
    <origin rpy="0 0 0" xyz="1.6627288388325575e-18 -0.023321469750082598 0.01528678511420778"/>
    <mass value="0.0023208419487673695"/>
    <inertia ixx="1e-06" ixy="0.0" ixz="0.0" iyy="0.0" iyz="0.0" izz="0.0"/>
  </inertial>
  <visual>
    <origin rpy="0 0 0" xyz="-0.0 0.01 -0.05"/>
    <geometry>
      <mesh filename="package://center_table_description/meshes/Component3_1.stl" scale="0.001 0.001 0.001"/>
    </geometry>
    <material name="silver"/>
  </visual>
  <collision>
    <origin rpy="0 0 0" xyz="-0.0 0.01 -0.05"/>
    <geometry>
      <mesh filename="package://center_table_description/meshes/Component3_1.stl" scale="0.001 0.001 0.001"/>
    </geometry>
  </collision>
</link>

<link name="Component5_1">
  <inertial>
    <origin rpy="0 0 0" xyz="0.06450691874368497 4.0364239166402594e-18 0.021358208696636627"/>
    <mass value="0.004666664302202742"/>
    <inertia ixx="0.0" ixy="-0.0" ixz="-0.0" iyy="1e-06" iyz="-0.0" izz="0.0"/>
  </inertial>
  <visual>
    <origin rpy="0 0 0" xyz="-0.022702 0.0 -0.079371"/>
    <geometry>
      <mesh filename="package://center_table_description/meshes/Component5_1.stl" scale="0.001 0.001 0.001"/>
    </geometry>
    <material name="silver"/>
  </visual>
  <collision>
    <origin rpy="0 0 0" xyz="-0.022702 0.0 -0.079371"/>
    <geometry>
      <mesh filename="package://center_table_description/meshes/Component5_1.stl" scale="0.001 0.001 0.001"/>
    </geometry>
  </collision>
</link>

<link name="Component6_1">
  <inertial>
    <origin rpy="0 0 0" xyz="0.023304819592421956 -6.58763579511824e-19 0.015312156418893066"/>
    <mass value="0.002320841948767369"/>
    <inertia ixx="0.0" ixy="-0.0" ixz="-0.0" iyy="1e-06" iyz="0.0" izz="0.0"/>
  </inertial>
  <visual>
    <origin rpy="0 0 0" xyz="-0.01 0.0 -0.05"/>
    <geometry>
      <mesh filename="package://center_table_description/meshes/Component6_1.stl" scale="0.001 0.001 0.001"/>
    </geometry>
    <material name="silver"/>
  </visual>
  <collision>
    <origin rpy="0 0 0" xyz="-0.01 0.0 -0.05"/>
    <geometry>
      <mesh filename="package://center_table_description/meshes/Component6_1.stl" scale="0.001 0.001 0.001"/>
    </geometry>
  </collision>
</link>

<link name="Component2_1">
  <inertial>
    <origin rpy="0 0 0" xyz="9.946911146715134e-06 -2.6926746929132578e-05 0.012493048295286788"/>
    <mass value="3.142431822521174"/>
    <inertia ixx="0.010498" ixy="0.0" ixz="-7e-06" iyy="0.010498" iyz="-7e-06" izz="0.020944"/>
  </inertial>
  <visual>
    <origin rpy="0 0 0" xyz="-0.0 -0.0 -0.1"/>
    <geometry>
      <mesh filename="package://center_table_description/meshes/Component2_1.stl" scale="0.001 0.001 0.001"/>
    </geometry>
    <material name="silver"/>
  </visual>
  <collision>
    <origin rpy="0 0 0" xyz="-0.0 -0.0 -0.1"/>
    <geometry>
      <mesh filename="package://center_table_description/meshes/Component2_1.stl" scale="0.001 0.001 0.001"/>
    </geometry>
  </collision>
</link>

<link name="Component2_1">
  <inertial>
    <origin rpy="0 0 0" xyz="9.946911146715134e-06 0.08997507325307087 0.01005304829528679"/>
    <mass value="3.142431822521174"/>
    <inertia ixx="0.010498" ixy="0.0" ixz="-7e-06" iyy="0.010498" iyz="-7e-06" izz="0.020944"/>
  </inertial>
  <visual>
    <origin rpy="0 0 0" xyz="-0.0 0.090002 -0.10244"/>
    <geometry>
      <mesh filename="package://center_table_description/meshes/Component2_1.stl" scale="0.001 0.001 0.001"/>
    </geometry>
    <material name="silver"/>
  </visual>
  <collision>
    <origin rpy="0 0 0" xyz="-0.0 0.090002 -0.10244"/>
    <geometry>
      <mesh filename="package://center_table_description/meshes/Component2_1.stl" scale="0.001 0.001 0.001"/>
    </geometry>
  </collision>
</link>

<link name="Component2_1">
  <inertial>
    <origin rpy="0 0 0" xyz="-0.08998805308885328 -2.6926746929132578e-05 0.009931048295286793"/>
    <mass value="3.142431822521174"/>
    <inertia ixx="0.010498" ixy="0.0" ixz="-7e-06" iyy="0.010498" iyz="-7e-06" izz="0.020944"/>
  </inertial>
  <visual>
    <origin rpy="0 0 0" xyz="-0.089998 -0.0 -0.102562"/>
    <geometry>
      <mesh filename="package://center_table_description/meshes/Component2_1.stl" scale="0.001 0.001 0.001"/>
    </geometry>
    <material name="silver"/>
  </visual>
  <collision>
    <origin rpy="0 0 0" xyz="-0.089998 -0.0 -0.102562"/>
    <geometry>
      <mesh filename="package://center_table_description/meshes/Component2_1.stl" scale="0.001 0.001 0.001"/>
    </geometry>
  </collision>
</link>

<joint name="Slider1" type="prismatic">
  <origin rpy="0 0 0" xyz="0.0 -0.012766 0.029343"/>
  <parent link="Component3_1"/>
  <child link="Component4_1"/>
  <axis xyz="0.0 -0.836343 0.548207"/>
  <limit effort="100" lower="0.0" upper="0.026" velocity="100"/>
</joint>

<joint name="Rev2" type="revolute">
  <origin rpy="0 0 0" xyz="0.0 -0.01 0.05"/>
  <parent link="base_link"/>
  <child link="Component3_1"/>
  <axis xyz="1.0 0.0 0.0"/>
  <limit effort="100" lower="-1.047198" upper="0.0" velocity="100"/>
</joint>

<joint name="Slider3" type="prismatic">
  <origin rpy="0 0 0" xyz="0.012702 0.0 0.029371"/>
  <parent link="Component6_1"/>
  <child link="Component5_1"/>
  <axis xyz="0.835746 -0.0 0.549117"/>
  <limit effort="100" lower="0.0" upper="0.026" velocity="100"/>
</joint>

<joint name="Rev4" type="revolute">
  <origin rpy="0 0 0" xyz="0.01 0.0 0.05"/>
  <parent link="base_link"/>
  <child link="Component6_1"/>
  <axis xyz="0.0 1.0 0.0"/>
  <limit effort="100" lower="-1.047198" upper="0.0" velocity="100"/>
</joint>

<joint name="Ball5" type="Ball">
  <origin rpy="0 0 0" xyz="0.089998 0.0 0.102562"/>
  <parent link="base_link"/>
  <child link="Component2_1"/>
</joint>

<joint name="Ball6" type="Ball">
  <origin rpy="0 0 0" xyz="0.089998 0.022766 0.023219"/>
  <parent link="Component4_1"/>
  <child link="Component2_1"/>
</joint>

<joint name="Ball7" type="Ball">
  <origin rpy="0 0 0" xyz="0.067296 0.0 0.023191"/>
  <parent link="Component5_1"/>
  <child link="Component2_1"/>
</joint>

</robot>
