<?xml version="1.0" ?>
<robot name="four_actuator_table" xmlns:xacro="http://www.ros.org/wiki/xacro">

<xacro:include filename="$(find four_actuator_table_description)/urdf/materials.xacro" />
<xacro:include filename="$(find four_actuator_table_description)/urdf/four_actuator_table.trans" />
<xacro:include filename="$(find four_actuator_table_description)/urdf/four_actuator_table.gazebo" />
<link name="base_link">
  <inertial>
    <origin rpy="0 0 0" xyz="1.0134632984844616e-12 -2.693232257466015e-17 0.0075072679770429385"/>
    <mass value="10.603665375127905"/>
    <inertia ixx="0.079785" ixy="-0.0" ixz="-0.0" iyy="0.079785" iyz="-0.0" izz="0.159171"/>
  </inertial>
  <visual>
    <origin rpy="0 0 0" xyz="0 0 0"/>
    <geometry>
      <mesh filename="package://four_actuator_table_description/meshes/base_link.stl" scale="0.001 0.001 0.001"/>
    </geometry>
    <material name="silver"/>
  </visual>
  <collision>
    <origin rpy="0 0 0" xyz="0 0 0"/>
    <geometry>
      <mesh filename="package://four_actuator_table_description/meshes/base_link.stl" scale="0.001 0.001 0.001"/>
    </geometry>
  </collision>
</link>

<link name="Component9_1">
  <inertial>
    <origin rpy="0 0 0" xyz="7.661691753257927e-09 5.7243641216064844e-09 -0.02948217736870809"/>
    <mass value="0.009387990911312292"/>
    <inertia ixx="1e-05" ixy="-0.0" ixz="0.0" iyy="1e-05" iyz="0.0" izz="0.0"/>
  </inertial>
  <visual>
    <origin rpy="0 0 0" xyz="0.13 0.13 -0.12933"/>
    <geometry>
      <mesh filename="package://four_actuator_table_description/meshes/Component9_1.stl" scale="0.001 0.001 0.001"/>
    </geometry>
    <material name="silver"/>
  </visual>
  <collision>
    <origin rpy="0 0 0" xyz="0.13 0.13 -0.12933"/>
    <geometry>
      <mesh filename="package://four_actuator_table_description/meshes/Component9_1.stl" scale="0.001 0.001 0.001"/>
    </geometry>
  </collision>
</link>

<link name="Component8_1">
  <inertial>
    <origin rpy="0 0 0" xyz="-3.787035074420686e-09 5.724362650560977e-09 -0.029482177368706286"/>
    <mass value="0.009387990911312233"/>
    <inertia ixx="1e-05" ixy="0.0" ixz="-0.0" iyy="1e-05" iyz="0.0" izz="0.0"/>
  </inertial>
  <visual>
    <origin rpy="0 0 0" xyz="-0.13 0.13 -0.12933"/>
    <geometry>
      <mesh filename="package://four_actuator_table_description/meshes/Component8_1.stl" scale="0.001 0.001 0.001"/>
    </geometry>
    <material name="silver"/>
  </visual>
  <collision>
    <origin rpy="0 0 0" xyz="-0.13 0.13 -0.12933"/>
    <geometry>
      <mesh filename="package://four_actuator_table_description/meshes/Component8_1.stl" scale="0.001 0.001 0.001"/>
    </geometry>
  </collision>
</link>

<link name="Component6_1">
  <inertial>
    <origin rpy="0 0 0" xyz="-3.787036545466194e-09 -5.724364177117636e-09 -0.02948217736870809"/>
    <mass value="0.009387990911312292"/>
    <inertia ixx="1e-05" ixy="-0.0" ixz="-0.0" iyy="1e-05" iyz="-0.0" izz="0.0"/>
  </inertial>
  <visual>
    <origin rpy="0 0 0" xyz="-0.13 -0.13 -0.12933"/>
    <geometry>
      <mesh filename="package://four_actuator_table_description/meshes/Component6_1.stl" scale="0.001 0.001 0.001"/>
    </geometry>
    <material name="silver"/>
  </visual>
  <collision>
    <origin rpy="0 0 0" xyz="-0.13 -0.13 -0.12933"/>
    <geometry>
      <mesh filename="package://four_actuator_table_description/meshes/Component6_1.stl" scale="0.001 0.001 0.001"/>
    </geometry>
  </collision>
</link>

<link name="Component4_1">
  <inertial>
    <origin rpy="0 0 0" xyz="1.4091686428852057e-09 -5.279210957276348e-10 0.03639054669746204"/>
    <mass value="0.013525671943771078"/>
    <inertia ixx="1.5e-05" ixy="-0.0" ixz="-0.0" iyy="1.5e-05" iyz="-0.0" izz="0.0"/>
  </inertial>
  <visual>
    <origin rpy="0 0 0" xyz="-0.13 -0.13 -0.025"/>
    <geometry>
      <mesh filename="package://four_actuator_table_description/meshes/Component4_1.stl" scale="0.001 0.001 0.001"/>
    </geometry>
    <material name="silver"/>
  </visual>
  <collision>
    <origin rpy="0 0 0" xyz="-0.13 -0.13 -0.025"/>
    <geometry>
      <mesh filename="package://four_actuator_table_description/meshes/Component4_1.stl" scale="0.001 0.001 0.001"/>
    </geometry>
  </collision>
</link>

<link name="Component5_1">
  <inertial>
    <origin rpy="0 0 0" xyz="1.4091685596184789e-09 5.280436365939778e-10 0.03639054677869009"/>
    <mass value="0.01352567194377108"/>
    <inertia ixx="1.5e-05" ixy="0.0" ixz="-0.0" iyy="1.5e-05" iyz="0.0" izz="0.0"/>
  </inertial>
  <visual>
    <origin rpy="0 0 0" xyz="-0.13 0.13 -0.025"/>
    <geometry>
      <mesh filename="package://four_actuator_table_description/meshes/Component5_1.stl" scale="0.001 0.001 0.001"/>
    </geometry>
    <material name="silver"/>
  </visual>
  <collision>
    <origin rpy="0 0 0" xyz="-0.13 0.13 -0.025"/>
    <geometry>
      <mesh filename="package://four_actuator_table_description/meshes/Component5_1.stl" scale="0.001 0.001 0.001"/>
    </geometry>
  </collision>
</link>

<link name="Component3_1">
  <inertial>
    <origin rpy="0 0 0" xyz="2.465133319695667e-09 5.280436365939778e-10 0.03639054677869009"/>
    <mass value="0.01352567194377108"/>
    <inertia ixx="1.5e-05" ixy="-0.0" ixz="0.0" iyy="1.5e-05" iyz="0.0" izz="0.0"/>
  </inertial>
  <visual>
    <origin rpy="0 0 0" xyz="0.13 0.13 -0.025"/>
    <geometry>
      <mesh filename="package://four_actuator_table_description/meshes/Component3_1.stl" scale="0.001 0.001 0.001"/>
    </geometry>
    <material name="silver"/>
  </visual>
  <collision>
    <origin rpy="0 0 0" xyz="0.13 0.13 -0.025"/>
    <geometry>
      <mesh filename="package://four_actuator_table_description/meshes/Component3_1.stl" scale="0.001 0.001 0.001"/>
    </geometry>
  </collision>
</link>

<link name="Component2_1">
  <inertial>
    <origin rpy="0 0 0" xyz="2.465133319695667e-09 -5.279210957276348e-10 0.03639054677869009"/>
    <mass value="0.01352567194377108"/>
    <inertia ixx="1.5e-05" ixy="0.0" ixz="0.0" iyy="1.5e-05" iyz="-0.0" izz="0.0"/>
  </inertial>
  <visual>
    <origin rpy="0 0 0" xyz="0.13 -0.13 -0.025"/>
    <geometry>
      <mesh filename="package://four_actuator_table_description/meshes/Component2_1.stl" scale="0.001 0.001 0.001"/>
    </geometry>
    <material name="silver"/>
  </visual>
  <collision>
    <origin rpy="0 0 0" xyz="0.13 -0.13 -0.025"/>
    <geometry>
      <mesh filename="package://four_actuator_table_description/meshes/Component2_1.stl" scale="0.001 0.001 0.001"/>
    </geometry>
  </collision>
</link>

<link name="Component7_1">
  <inertial>
    <origin rpy="0 0 0" xyz="7.661691753257927e-09 -5.724364177117636e-09 0.07051782263129189"/>
    <mass value="0.009387990911312292"/>
    <inertia ixx="1e-05" ixy="0.0" ixz="0.0" iyy="1e-05" iyz="-0.0" izz="0.0"/>
  </inertial>
  <visual>
    <origin rpy="0 0 0" xyz="0.13 -0.13 -0.02933"/>
    <geometry>
      <mesh filename="package://four_actuator_table_description/meshes/Component7_1.stl" scale="0.001 0.001 0.001"/>
    </geometry>
    <material name="silver"/>
  </visual>
  <collision>
    <origin rpy="0 0 0" xyz="0.13 -0.13 -0.02933"/>
    <geometry>
      <mesh filename="package://four_actuator_table_description/meshes/Component7_1.stl" scale="0.001 0.001 0.001"/>
    </geometry>
  </collision>
</link>

<link name="Component6_1">
  <inertial>
    <origin rpy="0 0 0" xyz="-3.787036545466194e-09 -5.724364177117636e-09 0.07051782263129192"/>
    <mass value="0.009387990911312292"/>
    <inertia ixx="1e-05" ixy="-0.0" ixz="-0.0" iyy="1e-05" iyz="-0.0" izz="0.0"/>
  </inertial>
  <visual>
    <origin rpy="0 0 0" xyz="-0.13 -0.13 -0.02933"/>
    <geometry>
      <mesh filename="package://four_actuator_table_description/meshes/Component6_1.stl" scale="0.001 0.001 0.001"/>
    </geometry>
    <material name="silver"/>
  </visual>
  <collision>
    <origin rpy="0 0 0" xyz="-0.13 -0.13 -0.02933"/>
    <geometry>
      <mesh filename="package://four_actuator_table_description/meshes/Component6_1.stl" scale="0.001 0.001 0.001"/>
    </geometry>
  </collision>
</link>

<link name="Component8_1">
  <inertial>
    <origin rpy="0 0 0" xyz="-3.787035074420686e-09 5.724362650560977e-09 0.07051782263129372"/>
    <mass value="0.009387990911312233"/>
    <inertia ixx="1e-05" ixy="0.0" ixz="-0.0" iyy="1e-05" iyz="0.0" izz="0.0"/>
  </inertial>
  <visual>
    <origin rpy="0 0 0" xyz="-0.13 0.13 -0.02933"/>
    <geometry>
      <mesh filename="package://four_actuator_table_description/meshes/Component8_1.stl" scale="0.001 0.001 0.001"/>
    </geometry>
    <material name="silver"/>
  </visual>
  <collision>
    <origin rpy="0 0 0" xyz="-0.13 0.13 -0.02933"/>
    <geometry>
      <mesh filename="package://four_actuator_table_description/meshes/Component8_1.stl" scale="0.001 0.001 0.001"/>
    </geometry>
  </collision>
</link>

<link name="Component9_1">
  <inertial>
    <origin rpy="0 0 0" xyz="7.661691753257927e-09 5.7243641216064844e-09 0.07051782263129192"/>
    <mass value="0.009387990911312292"/>
    <inertia ixx="1e-05" ixy="-0.0" ixz="0.0" iyy="1e-05" iyz="0.0" izz="0.0"/>
  </inertial>
  <visual>
    <origin rpy="0 0 0" xyz="0.13 0.13 -0.02933"/>
    <geometry>
      <mesh filename="package://four_actuator_table_description/meshes/Component9_1.stl" scale="0.001 0.001 0.001"/>
    </geometry>
    <material name="silver"/>
  </visual>
  <collision>
    <origin rpy="0 0 0" xyz="0.13 0.13 -0.02933"/>
    <geometry>
      <mesh filename="package://four_actuator_table_description/meshes/Component9_1.stl" scale="0.001 0.001 0.001"/>
    </geometry>
  </collision>
</link>

<link name="Component10_1">
  <inertial>
    <origin rpy="0 0 0" xyz="0.13000000387385152 -0.12999999999999992 0.0174928594785429"/>
    <mass value="10.603665375954742"/>
    <inertia ixx="0.079785" ixy="0.0" ixz="-0.0" iyy="0.079785" iyz="0.0" izz="0.159171"/>
  </inertial>
  <visual>
    <origin rpy="0 0 0" xyz="0.13 -0.13 -0.12933"/>
    <geometry>
      <mesh filename="package://four_actuator_table_description/meshes/Component10_1.stl" scale="0.001 0.001 0.001"/>
    </geometry>
    <material name="silver"/>
  </visual>
  <collision>
    <origin rpy="0 0 0" xyz="0.13 -0.13 -0.12933"/>
    <geometry>
      <mesh filename="package://four_actuator_table_description/meshes/Component10_1.stl" scale="0.001 0.001 0.001"/>
    </geometry>
  </collision>
</link>

<joint name="Rev2" type="continuous">
  <origin rpy="0 0 0" xyz="0.0 -0.26 -0.1"/>
  <parent link="Component10_1"/>
  <child link="Component9_1"/>
  <axis xyz="0.0 0.0 -1.0"/>
</joint>

<joint name="Rev3" type="continuous">
  <origin rpy="0 0 0" xyz="0.26 -0.26 -0.1"/>
  <parent link="Component10_1"/>
  <child link="Component8_1"/>
  <axis xyz="0.0 0.0 -1.0"/>
</joint>

<joint name="Rev4" type="continuous">
  <origin rpy="0 0 0" xyz="0.26 0.0 -0.1"/>
  <parent link="Component10_1"/>
  <child link="Component6_1"/>
  <axis xyz="0.0 -0.0 1.0"/>
</joint>

<joint name="Rev5" type="continuous">
  <origin rpy="0 0 0" xyz="0.13 0.13 0.025"/>
  <parent link="base_link"/>
  <child link="Component4_1"/>
  <axis xyz="0.0 -0.0 -1.0"/>
</joint>

<joint name="Rev6" type="continuous">
  <origin rpy="0 0 0" xyz="0.13 -0.13 0.025"/>
  <parent link="base_link"/>
  <child link="Component5_1"/>
  <axis xyz="0.0 0.0 1.0"/>
</joint>

<joint name="Rev7" type="continuous">
  <origin rpy="0 0 0" xyz="-0.13 -0.13 0.025"/>
  <parent link="base_link"/>
  <child link="Component3_1"/>
  <axis xyz="0.0 0.0 1.0"/>
</joint>

<joint name="Rev8" type="continuous">
  <origin rpy="0 0 0" xyz="-0.13 0.13 0.025"/>
  <parent link="base_link"/>
  <child link="Component2_1"/>
  <axis xyz="0.0 0.0 1.0"/>
</joint>

<joint name="Slider9" type="prismatic">
  <origin rpy="0 0 0" xyz="0.0 0.0 0.00433"/>
  <parent link="Component2_1"/>
  <child link="Component7_1"/>
  <axis xyz="0.0 0.0 -1.0"/>
  <limit effort="100" lower="-0.095" upper="0.0" velocity="100"/>
</joint>

<joint name="Slider10" type="prismatic">
  <origin rpy="0 0 0" xyz="0.0 0.0 0.00433"/>
  <parent link="Component4_1"/>
  <child link="Component6_1"/>
  <axis xyz="0.0 -0.0 -1.0"/>
  <limit effort="100" lower="-0.09" upper="0.0" velocity="100"/>
</joint>

<joint name="Slider11" type="prismatic">
  <origin rpy="0 0 0" xyz="0.0 0.0 0.00433"/>
  <parent link="Component5_1"/>
  <child link="Component8_1"/>
  <axis xyz="0.0 0.0 -1.0"/>
  <limit effort="100" lower="-0.095" upper="0.0" velocity="100"/>
</joint>

<joint name="Slider12" type="prismatic">
  <origin rpy="0 0 0" xyz="0.0 0.0 0.00433"/>
  <parent link="Component3_1"/>
  <child link="Component9_1"/>
  <axis xyz="0.0 0.0 -1.0"/>
  <limit effort="100" lower="-0.095" upper="0.0" velocity="100"/>
</joint>

<joint name="Rev1" type="continuous">
  <origin rpy="0 0 0" xyz="0.0 0.0 0.1"/>
  <parent link="Component7_1"/>
  <child link="Component10_1"/>
  <axis xyz="0.0 0.0 1.0"/>
</joint>

</robot>
